[2025-04-20T01:45:24.949+0000] {taskinstance.py:1956} INFO - Dependencies all met for dep_context=non-requeueable deps ti=<TaskInstance: prices_dag.save_to_excel manual__2025-04-20T01:44:14.178120+00:00 [queued]>
[2025-04-20T01:45:24.965+0000] {taskinstance.py:1956} INFO - Dependencies all met for dep_context=requeueable deps ti=<TaskInstance: prices_dag.save_to_excel manual__2025-04-20T01:44:14.178120+00:00 [queued]>
[2025-04-20T01:45:24.966+0000] {taskinstance.py:2170} INFO - Starting attempt 2 of 2
[2025-04-20T01:45:24.989+0000] {taskinstance.py:2191} INFO - Executing <Task(PythonOperator): save_to_excel> on 2025-04-20 01:44:14.178120+00:00
[2025-04-20T01:45:25.004+0000] {standard_task_runner.py:60} INFO - Started process 278 to run task
[2025-04-20T01:45:25.008+0000] {standard_task_runner.py:87} INFO - Running: ['***', 'tasks', 'run', 'prices_dag', 'save_to_excel', 'manual__2025-04-20T01:44:14.178120+00:00', '--job-id', '16', '--raw', '--subdir', 'DAGS_FOLDER/prices_dag.py', '--cfg-path', '/tmp/tmptp2ariz0']
[2025-04-20T01:45:25.013+0000] {standard_task_runner.py:88} INFO - Job 16: Subtask save_to_excel
[2025-04-20T01:45:25.211+0000] {task_command.py:423} INFO - Running <TaskInstance: prices_dag.save_to_excel manual__2025-04-20T01:44:14.178120+00:00 [running]> on host 5b72081ecd33
[2025-04-20T01:45:25.417+0000] {taskinstance.py:2480} INFO - Exporting env vars: AIRFLOW_CTX_DAG_OWNER='***' AIRFLOW_CTX_DAG_ID='prices_dag' AIRFLOW_CTX_TASK_ID='save_to_excel' AIRFLOW_CTX_EXECUTION_DATE='2025-04-20T01:44:14.178120+00:00' AIRFLOW_CTX_TRY_NUMBER='2' AIRFLOW_CTX_DAG_RUN_ID='manual__2025-04-20T01:44:14.178120+00:00'
[2025-04-20T01:45:25.799+0000] {taskinstance.py:2698} ERROR - Task failed with exception
Traceback (most recent call last):
  File "/home/airflow/.local/lib/python3.8/site-packages/airflow/models/taskinstance.py", line 433, in _execute_task
    result = execute_callable(context=context, **execute_callable_kwargs)
  File "/home/airflow/.local/lib/python3.8/site-packages/airflow/operators/python.py", line 199, in execute
    return_value = self.execute_callable()
  File "/home/airflow/.local/lib/python3.8/site-packages/airflow/operators/python.py", line 216, in execute_callable
    return self.python_callable(*self.op_args, **self.op_kwargs)
  File "/opt/airflow/dags/prices_dag.py", line 66, in save_to_excel
    df.to_excel(file_path, index=False)
  File "/home/airflow/.local/lib/python3.8/site-packages/pandas/core/generic.py", line 2252, in to_excel
    formatter.write(
  File "/home/airflow/.local/lib/python3.8/site-packages/pandas/io/formats/excel.py", line 934, in write
    writer = ExcelWriter(  # type: ignore[abstract]
  File "/home/airflow/.local/lib/python3.8/site-packages/pandas/io/excel/_openpyxl.py", line 60, in __init__
    super().__init__(
  File "/home/airflow/.local/lib/python3.8/site-packages/pandas/io/excel/_base.py", line 1219, in __init__
    self._handles = get_handle(
  File "/home/airflow/.local/lib/python3.8/site-packages/pandas/io/common.py", line 868, in get_handle
    handle = open(handle, ioargs.mode)
PermissionError: [Errno 13] Permission denied: '/opt/airflow/data/raw/tatasteel.xlsx'
[2025-04-20T01:45:25.826+0000] {taskinstance.py:1138} INFO - Marking task as FAILED. dag_id=prices_dag, task_id=save_to_excel, execution_date=20250420T014414, start_date=20250420T014524, end_date=20250420T014525
[2025-04-20T01:45:25.843+0000] {standard_task_runner.py:107} ERROR - Failed to execute job 16 for task save_to_excel ([Errno 13] Permission denied: '/opt/airflow/data/raw/tatasteel.xlsx'; 278)
[2025-04-20T01:45:25.868+0000] {local_task_job_runner.py:234} INFO - Task exited with return code 1
[2025-04-20T01:45:25.893+0000] {taskinstance.py:3280} INFO - 0 downstream tasks scheduled from follow-on schedule check
