[2025-04-24T18:53:05.996+0000] {taskinstance.py:1956} INFO - Dependencies all met for dep_context=non-requeueable deps ti=<TaskInstance: read_excel_from_mongo_dag_with_rsi.store_in_mysql_task manual__2025-04-24T18:52:58.259295+00:00 [queued]>
[2025-04-24T18:53:06.004+0000] {taskinstance.py:1956} INFO - Dependencies all met for dep_context=requeueable deps ti=<TaskInstance: read_excel_from_mongo_dag_with_rsi.store_in_mysql_task manual__2025-04-24T18:52:58.259295+00:00 [queued]>
[2025-04-24T18:53:06.004+0000] {taskinstance.py:2170} INFO - Starting attempt 1 of 2
[2025-04-24T18:53:06.017+0000] {taskinstance.py:2191} INFO - Executing <Task(_PythonDecoratedOperator): store_in_mysql_task> on 2025-04-24 18:52:58.259295+00:00
[2025-04-24T18:53:06.025+0000] {standard_task_runner.py:60} INFO - Started process 1327 to run task
[2025-04-24T18:53:06.028+0000] {standard_task_runner.py:87} INFO - Running: ['***', 'tasks', 'run', 'read_excel_from_mongo_dag_with_rsi', 'store_in_mysql_task', 'manual__2025-04-24T18:52:58.259295+00:00', '--job-id', '153', '--raw', '--subdir', 'DAGS_FOLDER/indicator_dag.py', '--cfg-path', '/tmp/tmphafhc5xa']
[2025-04-24T18:53:06.029+0000] {standard_task_runner.py:88} INFO - Job 153: Subtask store_in_mysql_task
[2025-04-24T18:53:06.072+0000] {task_command.py:423} INFO - Running <TaskInstance: read_excel_from_mongo_dag_with_rsi.store_in_mysql_task manual__2025-04-24T18:52:58.259295+00:00 [running]> on host 8291240c5d79
[2025-04-24T18:53:06.160+0000] {taskinstance.py:2480} INFO - Exporting env vars: AIRFLOW_CTX_DAG_OWNER='***' AIRFLOW_CTX_DAG_ID='read_excel_from_mongo_dag_with_rsi' AIRFLOW_CTX_TASK_ID='store_in_mysql_task' AIRFLOW_CTX_EXECUTION_DATE='2025-04-24T18:52:58.259295+00:00' AIRFLOW_CTX_TRY_NUMBER='1' AIRFLOW_CTX_DAG_RUN_ID='manual__2025-04-24T18:52:58.259295+00:00'
[2025-04-24T18:53:06.291+0000] {logging_mixin.py:188} INFO - âœ… Database `intermediate` ensured to exist.
[2025-04-24T18:53:06.299+0000] {taskinstance.py:2698} ERROR - Task failed with exception
Traceback (most recent call last):
  File "/home/airflow/.local/lib/python3.10/site-packages/airflow/models/taskinstance.py", line 433, in _execute_task
    result = execute_callable(context=context, **execute_callable_kwargs)
  File "/home/airflow/.local/lib/python3.10/site-packages/airflow/decorators/base.py", line 241, in execute
    return_value = super().execute(context)
  File "/home/airflow/.local/lib/python3.10/site-packages/airflow/operators/python.py", line 199, in execute
    return_value = self.execute_callable()
  File "/home/airflow/.local/lib/python3.10/site-packages/airflow/operators/python.py", line 216, in execute_callable
    return self.python_callable(*self.op_args, **self.op_kwargs)
  File "/opt/airflow/dags/indicator_dag.py", line 171, in store_in_mysql_task
    store_df_in_mysql(df, ticker)
  File "/opt/airflow/dags/indicator_dag.py", line 84, in store_df_in_mysql
    cursor.execute(create_table_query)
  File "/home/airflow/.local/lib/python3.10/site-packages/pymysql/cursors.py", line 153, in execute
    result = self._query(query)
  File "/home/airflow/.local/lib/python3.10/site-packages/pymysql/cursors.py", line 322, in _query
    conn.query(q)
  File "/home/airflow/.local/lib/python3.10/site-packages/pymysql/connections.py", line 563, in query
    self._affected_rows = self._read_query_result(unbuffered=unbuffered)
  File "/home/airflow/.local/lib/python3.10/site-packages/pymysql/connections.py", line 825, in _read_query_result
    result.read()
  File "/home/airflow/.local/lib/python3.10/site-packages/pymysql/connections.py", line 1199, in read
    first_packet = self.connection._read_packet()
  File "/home/airflow/.local/lib/python3.10/site-packages/pymysql/connections.py", line 775, in _read_packet
    packet.raise_for_error()
  File "/home/airflow/.local/lib/python3.10/site-packages/pymysql/protocol.py", line 219, in raise_for_error
    err.raise_mysql_exception(self._data)
  File "/home/airflow/.local/lib/python3.10/site-packages/pymysql/err.py", line 150, in raise_mysql_exception
    raise errorclass(errno, errval)
pymysql.err.OperationalError: (1049, "Unknown database 'tatasteel'")
[2025-04-24T18:53:06.320+0000] {taskinstance.py:1138} INFO - Marking task as UP_FOR_RETRY. dag_id=read_excel_from_mongo_dag_with_rsi, task_id=store_in_mysql_task, execution_date=20250424T185258, start_date=20250424T185305, end_date=20250424T185306
[2025-04-24T18:53:06.333+0000] {standard_task_runner.py:107} ERROR - Failed to execute job 153 for task store_in_mysql_task ((1049, "Unknown database 'tatasteel'"); 1327)
[2025-04-24T18:53:06.360+0000] {local_task_job_runner.py:234} INFO - Task exited with return code 1
[2025-04-24T18:53:06.380+0000] {taskinstance.py:3280} INFO - 0 downstream tasks scheduled from follow-on schedule check
