[2025-04-24T18:37:03.603+0000] {taskinstance.py:1956} INFO - Dependencies all met for dep_context=non-requeueable deps ti=<TaskInstance: read_excel_from_mongo_dag_with_rsi.fetch_excel_from_mongo manual__2025-04-24T18:36:59.733716+00:00 [queued]>
[2025-04-24T18:37:03.616+0000] {taskinstance.py:1956} INFO - Dependencies all met for dep_context=requeueable deps ti=<TaskInstance: read_excel_from_mongo_dag_with_rsi.fetch_excel_from_mongo manual__2025-04-24T18:36:59.733716+00:00 [queued]>
[2025-04-24T18:37:03.617+0000] {taskinstance.py:2170} INFO - Starting attempt 1 of 2
[2025-04-24T18:37:03.630+0000] {taskinstance.py:2191} INFO - Executing <Task(_PythonDecoratedOperator): fetch_excel_from_mongo> on 2025-04-24 18:36:59.733716+00:00
[2025-04-24T18:37:03.643+0000] {standard_task_runner.py:60} INFO - Started process 819 to run task
[2025-04-24T18:37:03.650+0000] {standard_task_runner.py:87} INFO - Running: ['***', 'tasks', 'run', 'read_excel_from_mongo_dag_with_rsi', 'fetch_excel_from_mongo', 'manual__2025-04-24T18:36:59.733716+00:00', '--job-id', '132', '--raw', '--subdir', 'DAGS_FOLDER/indicator_dag.py', '--cfg-path', '/tmp/tmpmzyu2xux']
[2025-04-24T18:37:03.652+0000] {standard_task_runner.py:88} INFO - Job 132: Subtask fetch_excel_from_mongo
[2025-04-24T18:37:03.836+0000] {task_command.py:423} INFO - Running <TaskInstance: read_excel_from_mongo_dag_with_rsi.fetch_excel_from_mongo manual__2025-04-24T18:36:59.733716+00:00 [running]> on host 8291240c5d79
[2025-04-24T18:37:04.651+0000] {taskinstance.py:2480} INFO - Exporting env vars: AIRFLOW_CTX_DAG_OWNER='***' AIRFLOW_CTX_DAG_ID='read_excel_from_mongo_dag_with_rsi' AIRFLOW_CTX_TASK_ID='fetch_excel_from_mongo' AIRFLOW_CTX_EXECUTION_DATE='2025-04-24T18:36:59.733716+00:00' AIRFLOW_CTX_TRY_NUMBER='1' AIRFLOW_CTX_DAG_RUN_ID='manual__2025-04-24T18:36:59.733716+00:00'
[2025-04-24T18:37:18.688+0000] {job.py:213} ERROR - Job heartbeat got an exception
Traceback (most recent call last):
  File "/home/airflow/.local/lib/python3.10/site-packages/sqlalchemy/engine/base.py", line 3371, in _wrap_pool_connect
    return fn()
  File "/home/airflow/.local/lib/python3.10/site-packages/sqlalchemy/pool/base.py", line 327, in connect
    return _ConnectionFairy._checkout(self)
  File "/home/airflow/.local/lib/python3.10/site-packages/sqlalchemy/pool/base.py", line 894, in _checkout
    fairy = _ConnectionRecord.checkout(pool)
  File "/home/airflow/.local/lib/python3.10/site-packages/sqlalchemy/pool/base.py", line 493, in checkout
    rec = pool._do_get()
  File "/home/airflow/.local/lib/python3.10/site-packages/sqlalchemy/pool/impl.py", line 256, in _do_get
    return self._create_connection()
  File "/home/airflow/.local/lib/python3.10/site-packages/sqlalchemy/pool/base.py", line 273, in _create_connection
    return _ConnectionRecord(self)
  File "/home/airflow/.local/lib/python3.10/site-packages/sqlalchemy/pool/base.py", line 388, in __init__
    self.__connect()
  File "/home/airflow/.local/lib/python3.10/site-packages/sqlalchemy/pool/base.py", line 690, in __connect
    with util.safe_reraise():
  File "/home/airflow/.local/lib/python3.10/site-packages/sqlalchemy/util/langhelpers.py", line 70, in __exit__
    compat.raise_(
  File "/home/airflow/.local/lib/python3.10/site-packages/sqlalchemy/util/compat.py", line 211, in raise_
    raise exception
  File "/home/airflow/.local/lib/python3.10/site-packages/sqlalchemy/pool/base.py", line 686, in __connect
    self.dbapi_connection = connection = pool._invoke_creator(self)
  File "/home/airflow/.local/lib/python3.10/site-packages/sqlalchemy/engine/create.py", line 574, in connect
    return dialect.connect(*cargs, **cparams)
  File "/home/airflow/.local/lib/python3.10/site-packages/sqlalchemy/engine/default.py", line 598, in connect
    return self.dbapi.connect(*cargs, **cparams)
  File "/home/airflow/.local/lib/python3.10/site-packages/psycopg2/__init__.py", line 122, in connect
    conn = _connect(dsn, connection_factory=connection_factory, **kwasync)
psycopg2.OperationalError: could not translate host name "postgres" to address: Temporary failure in name resolution


The above exception was the direct cause of the following exception:

Traceback (most recent call last):
  File "/home/airflow/.local/lib/python3.10/site-packages/airflow/jobs/job.py", line 187, in heartbeat
    self._merge_from(Job._fetch_from_db(self, session))
  File "/home/airflow/.local/lib/python3.10/site-packages/airflow/api_internal/internal_api_call.py", line 114, in wrapper
    return func(*args, **kwargs)
  File "/home/airflow/.local/lib/python3.10/site-packages/airflow/utils/session.py", line 76, in wrapper
    return func(*args, **kwargs)
  File "/home/airflow/.local/lib/python3.10/site-packages/airflow/jobs/job.py", line 308, in _fetch_from_db
    session.merge(job)
  File "/home/airflow/.local/lib/python3.10/site-packages/sqlalchemy/orm/session.py", line 3056, in merge
    return self._merge(
  File "/home/airflow/.local/lib/python3.10/site-packages/sqlalchemy/orm/session.py", line 3136, in _merge
    merged = self.get(
  File "/home/airflow/.local/lib/python3.10/site-packages/sqlalchemy/orm/session.py", line 2853, in get
    return self._get_impl(
  File "/home/airflow/.local/lib/python3.10/site-packages/sqlalchemy/orm/session.py", line 2975, in _get_impl
    return db_load_fn(
  File "/home/airflow/.local/lib/python3.10/site-packages/sqlalchemy/orm/loading.py", line 530, in load_on_pk_identity
    session.execute(
  File "/home/airflow/.local/lib/python3.10/site-packages/sqlalchemy/orm/session.py", line 1716, in execute
    conn = self._connection_for_bind(bind)
  File "/home/airflow/.local/lib/python3.10/site-packages/sqlalchemy/orm/session.py", line 1555, in _connection_for_bind
    return self._transaction._connection_for_bind(
  File "/home/airflow/.local/lib/python3.10/site-packages/sqlalchemy/orm/session.py", line 750, in _connection_for_bind
    conn = bind.connect()
  File "/home/airflow/.local/lib/python3.10/site-packages/sqlalchemy/future/engine.py", line 412, in connect
    return super(Engine, self).connect()
  File "/home/airflow/.local/lib/python3.10/site-packages/sqlalchemy/engine/base.py", line 3325, in connect
    return self._connection_cls(self, close_with_result=close_with_result)
  File "/home/airflow/.local/lib/python3.10/site-packages/sqlalchemy/engine/base.py", line 96, in __init__
    else engine.raw_connection()
  File "/home/airflow/.local/lib/python3.10/site-packages/sqlalchemy/engine/base.py", line 3404, in raw_connection
    return self._wrap_pool_connect(self.pool.connect, _connection)
  File "/home/airflow/.local/lib/python3.10/site-packages/sqlalchemy/engine/base.py", line 3374, in _wrap_pool_connect
    Connection._handle_dbapi_exception_noconnection(
  File "/home/airflow/.local/lib/python3.10/site-packages/sqlalchemy/engine/base.py", line 2208, in _handle_dbapi_exception_noconnection
    util.raise_(
  File "/home/airflow/.local/lib/python3.10/site-packages/sqlalchemy/util/compat.py", line 211, in raise_
    raise exception
  File "/home/airflow/.local/lib/python3.10/site-packages/sqlalchemy/engine/base.py", line 3371, in _wrap_pool_connect
    return fn()
  File "/home/airflow/.local/lib/python3.10/site-packages/sqlalchemy/pool/base.py", line 327, in connect
    return _ConnectionFairy._checkout(self)
  File "/home/airflow/.local/lib/python3.10/site-packages/sqlalchemy/pool/base.py", line 894, in _checkout
    fairy = _ConnectionRecord.checkout(pool)
  File "/home/airflow/.local/lib/python3.10/site-packages/sqlalchemy/pool/base.py", line 493, in checkout
    rec = pool._do_get()
  File "/home/airflow/.local/lib/python3.10/site-packages/sqlalchemy/pool/impl.py", line 256, in _do_get
    return self._create_connection()
  File "/home/airflow/.local/lib/python3.10/site-packages/sqlalchemy/pool/base.py", line 273, in _create_connection
    return _ConnectionRecord(self)
  File "/home/airflow/.local/lib/python3.10/site-packages/sqlalchemy/pool/base.py", line 388, in __init__
    self.__connect()
  File "/home/airflow/.local/lib/python3.10/site-packages/sqlalchemy/pool/base.py", line 690, in __connect
    with util.safe_reraise():
  File "/home/airflow/.local/lib/python3.10/site-packages/sqlalchemy/util/langhelpers.py", line 70, in __exit__
    compat.raise_(
  File "/home/airflow/.local/lib/python3.10/site-packages/sqlalchemy/util/compat.py", line 211, in raise_
    raise exception
  File "/home/airflow/.local/lib/python3.10/site-packages/sqlalchemy/pool/base.py", line 686, in __connect
    self.dbapi_connection = connection = pool._invoke_creator(self)
  File "/home/airflow/.local/lib/python3.10/site-packages/sqlalchemy/engine/create.py", line 574, in connect
    return dialect.connect(*cargs, **cparams)
  File "/home/airflow/.local/lib/python3.10/site-packages/sqlalchemy/engine/default.py", line 598, in connect
    return self.dbapi.connect(*cargs, **cparams)
  File "/home/airflow/.local/lib/python3.10/site-packages/psycopg2/__init__.py", line 122, in connect
    conn = _connect(dsn, connection_factory=connection_factory, **kwasync)
sqlalchemy.exc.OperationalError: (psycopg2.OperationalError) could not translate host name "postgres" to address: Temporary failure in name resolution

(Background on this error at: https://sqlalche.me/e/14/e3q8)
[2025-04-24T18:37:18.727+0000] {job.py:221} ERROR - Job heartbeat failed with error. Scheduler is in unhealthy state
[2025-04-24T18:37:36.991+0000] {job.py:221} ERROR - Job heartbeat failed with error. Scheduler is in unhealthy state
[2025-04-24T18:37:38.057+0000] {taskinstance.py:2698} ERROR - Task failed with exception
Traceback (most recent call last):
  File "/home/airflow/.local/lib/python3.10/site-packages/airflow/models/taskinstance.py", line 433, in _execute_task
    result = execute_callable(context=context, **execute_callable_kwargs)
  File "/home/airflow/.local/lib/python3.10/site-packages/airflow/decorators/base.py", line 241, in execute
    return_value = super().execute(context)
  File "/home/airflow/.local/lib/python3.10/site-packages/airflow/operators/python.py", line 199, in execute
    return_value = self.execute_callable()
  File "/home/airflow/.local/lib/python3.10/site-packages/airflow/operators/python.py", line 216, in execute_callable
    return self.python_callable(*self.op_args, **self.op_kwargs)
  File "/opt/airflow/dags/indicator_dag.py", line 132, in fetch_excel_from_mongo
    file_doc = collection.find_one(sort=[("upload_time", -1)])
  File "/home/airflow/.local/lib/python3.10/site-packages/pymongo/synchronous/collection.py", line 1755, in find_one
    for result in cursor.limit(-1):
  File "/home/airflow/.local/lib/python3.10/site-packages/pymongo/synchronous/cursor.py", line 1284, in __next__
    return self.next()
  File "/home/airflow/.local/lib/python3.10/site-packages/pymongo/synchronous/cursor.py", line 1260, in next
    if len(self._data) or self._refresh():
  File "/home/airflow/.local/lib/python3.10/site-packages/pymongo/synchronous/cursor.py", line 1208, in _refresh
    self._send_message(q)
  File "/home/airflow/.local/lib/python3.10/site-packages/pymongo/synchronous/cursor.py", line 1102, in _send_message
    response = client._run_operation(
  File "/home/airflow/.local/lib/python3.10/site-packages/pymongo/_csot.py", line 119, in csot_wrapper
    return func(self, *args, **kwargs)
  File "/home/airflow/.local/lib/python3.10/site-packages/pymongo/synchronous/mongo_client.py", line 1896, in _run_operation
    return self._retryable_read(
  File "/home/airflow/.local/lib/python3.10/site-packages/pymongo/synchronous/mongo_client.py", line 2005, in _retryable_read
    return self._retry_internal(
  File "/home/airflow/.local/lib/python3.10/site-packages/pymongo/_csot.py", line 119, in csot_wrapper
    return func(self, *args, **kwargs)
  File "/home/airflow/.local/lib/python3.10/site-packages/pymongo/synchronous/mongo_client.py", line 1972, in _retry_internal
    ).run()
  File "/home/airflow/.local/lib/python3.10/site-packages/pymongo/synchronous/mongo_client.py", line 2709, in run
    return self._read() if self._is_read else self._write()
  File "/home/airflow/.local/lib/python3.10/site-packages/pymongo/synchronous/mongo_client.py", line 2854, in _read
    self._server = self._get_server()
  File "/home/airflow/.local/lib/python3.10/site-packages/pymongo/synchronous/mongo_client.py", line 2802, in _get_server
    return self._client._select_server(
  File "/home/airflow/.local/lib/python3.10/site-packages/pymongo/synchronous/mongo_client.py", line 1791, in _select_server
    server = topology.select_server(
  File "/home/airflow/.local/lib/python3.10/site-packages/pymongo/synchronous/topology.py", line 409, in select_server
    server = self._select_server(
  File "/home/airflow/.local/lib/python3.10/site-packages/pymongo/synchronous/topology.py", line 387, in _select_server
    servers = self.select_servers(
  File "/home/airflow/.local/lib/python3.10/site-packages/pymongo/synchronous/topology.py", line 294, in select_servers
    server_descriptions = self._select_servers_loop(
  File "/home/airflow/.local/lib/python3.10/site-packages/pymongo/synchronous/topology.py", line 344, in _select_servers_loop
    raise ServerSelectionTimeoutError(
pymongo.errors.ServerSelectionTimeoutError: host.docker.internal:27017: [Errno -3] Temporary failure in name resolution (configured timeouts: socketTimeoutMS: 20000.0ms, connectTimeoutMS: 20000.0ms), Timeout: 30s, Topology Description: <TopologyDescription id: 680a84d0a83e0bb95d077e91, topology_type: Unknown, servers: [<ServerDescription ('host.docker.internal', 27017) server_type: Unknown, rtt: None, error=AutoReconnect('host.docker.internal:27017: [Errno -3] Temporary failure in name resolution (configured timeouts: socketTimeoutMS: 20000.0ms, connectTimeoutMS: 20000.0ms)')>]>
[2025-04-24T18:37:45.695+0000] {taskinstance.py:1138} INFO - Marking task as UP_FOR_RETRY. dag_id=read_excel_from_mongo_dag_with_rsi, task_id=fetch_excel_from_mongo, execution_date=20250424T183659, start_date=20250424T183703, end_date=20250424T183745
[2025-04-24T18:37:42.393+0000] {standard_task_runner.py:107} ERROR - Failed to execute job 132 for task fetch_excel_from_mongo (host.docker.internal:27017: [Errno -3] Temporary failure in name resolution (configured timeouts: socketTimeoutMS: 20000.0ms, connectTimeoutMS: 20000.0ms), Timeout: 30s, Topology Description: <TopologyDescription id: 680a84d0a83e0bb95d077e91, topology_type: Unknown, servers: [<ServerDescription ('host.docker.internal', 27017) server_type: Unknown, rtt: None, error=AutoReconnect('host.docker.internal:27017: [Errno -3] Temporary failure in name resolution (configured timeouts: socketTimeoutMS: 20000.0ms, connectTimeoutMS: 20000.0ms)')>]>; 819)
[2025-04-24T18:37:47.806+0000] {local_task_job_runner.py:234} INFO - Task exited with return code 1
[2025-04-24T18:37:47.928+0000] {taskinstance.py:3280} INFO - 0 downstream tasks scheduled from follow-on schedule check
