[2025-04-21T15:07:19.421+0000] {taskinstance.py:1956} INFO - Dependencies all met for dep_context=non-requeueable deps ti=<TaskInstance: prices_dag.save_to_excel manual__2025-04-21T15:07:09.056119+00:00 [queued]>
[2025-04-21T15:07:19.436+0000] {taskinstance.py:1956} INFO - Dependencies all met for dep_context=requeueable deps ti=<TaskInstance: prices_dag.save_to_excel manual__2025-04-21T15:07:09.056119+00:00 [queued]>
[2025-04-21T15:07:19.437+0000] {taskinstance.py:2170} INFO - Starting attempt 1 of 2
[2025-04-21T15:07:19.462+0000] {taskinstance.py:2191} INFO - Executing <Task(PythonOperator): save_to_excel> on 2025-04-21 15:07:09.056119+00:00
[2025-04-21T15:07:19.472+0000] {standard_task_runner.py:60} INFO - Started process 250 to run task
[2025-04-21T15:07:19.479+0000] {standard_task_runner.py:87} INFO - Running: ['***', 'tasks', 'run', 'prices_dag', 'save_to_excel', 'manual__2025-04-21T15:07:09.056119+00:00', '--job-id', '32', '--raw', '--subdir', 'DAGS_FOLDER/prices_dag.py', '--cfg-path', '/tmp/tmpn7cpllv9']
[2025-04-21T15:07:19.482+0000] {standard_task_runner.py:88} INFO - Job 32: Subtask save_to_excel
[2025-04-21T15:07:19.555+0000] {task_command.py:423} INFO - Running <TaskInstance: prices_dag.save_to_excel manual__2025-04-21T15:07:09.056119+00:00 [running]> on host 2950136dce1f
[2025-04-21T15:07:19.650+0000] {taskinstance.py:2480} INFO - Exporting env vars: AIRFLOW_CTX_DAG_OWNER='***' AIRFLOW_CTX_DAG_ID='prices_dag' AIRFLOW_CTX_TASK_ID='save_to_excel' AIRFLOW_CTX_EXECUTION_DATE='2025-04-21T15:07:09.056119+00:00' AIRFLOW_CTX_TRY_NUMBER='1' AIRFLOW_CTX_DAG_RUN_ID='manual__2025-04-21T15:07:09.056119+00:00'
[2025-04-21T15:07:19.673+0000] {logging_mixin.py:188} WARNING - /opt/***/dags/prices_dag.py:72 FutureWarning: Passing literal json to 'read_json' is deprecated and will be removed in a future version. To read from a literal string, wrap it in a 'StringIO' object.
[2025-04-21T15:07:19.905+0000] {logging_mixin.py:188} INFO - prices_data
[2025-04-21T15:07:19.905+0000] {logging_mixin.py:188} INFO - <class 'str'>
[2025-04-21T15:07:19.906+0000] {logging_mixin.py:188} INFO - mongodb host --> mongodb://localhost:27017/
[2025-04-21T15:07:19.907+0000] {logging_mixin.py:188} WARNING - /home/***/.local/lib/python3.10/site-packages/pymongo/synchronous/mongo_client.py:2709 UserWarning: MongoClient opened before fork. May not be entirely fork-safe, proceed with caution. See PyMongo's documentation for details: https://dochub.mongodb.org/core/pymongo-fork-deadlock
[2025-04-21T15:07:52.699+0000] {taskinstance.py:2698} ERROR - Task failed with exception
Traceback (most recent call last):
  File "/home/airflow/.local/lib/python3.10/site-packages/airflow/models/taskinstance.py", line 433, in _execute_task
    result = execute_callable(context=context, **execute_callable_kwargs)
  File "/home/airflow/.local/lib/python3.10/site-packages/airflow/operators/python.py", line 199, in execute
    return_value = self.execute_callable()
  File "/home/airflow/.local/lib/python3.10/site-packages/airflow/operators/python.py", line 216, in execute_callable
    return self.python_callable(*self.op_args, **self.op_kwargs)
  File "/opt/airflow/dags/prices_dag.py", line 79, in save_to_excel
    save_to_mongo(file_path)
  File "/opt/airflow/dags/prices_dag.py", line 101, in save_to_mongo
    collection.insert_one(file_doc)
  File "/home/airflow/.local/lib/python3.10/site-packages/pymongo/synchronous/collection.py", line 891, in insert_one
    self._insert_one(
  File "/home/airflow/.local/lib/python3.10/site-packages/pymongo/synchronous/collection.py", line 831, in _insert_one
    self._database.client._retryable_write(
  File "/home/airflow/.local/lib/python3.10/site-packages/pymongo/synchronous/mongo_client.py", line 2040, in _retryable_write
    return self._retry_with_session(retryable, func, s, bulk, operation, operation_id)
  File "/home/airflow/.local/lib/python3.10/site-packages/pymongo/synchronous/mongo_client.py", line 1926, in _retry_with_session
    return self._retry_internal(
  File "/home/airflow/.local/lib/python3.10/site-packages/pymongo/_csot.py", line 119, in csot_wrapper
    return func(self, *args, **kwargs)
  File "/home/airflow/.local/lib/python3.10/site-packages/pymongo/synchronous/mongo_client.py", line 1972, in _retry_internal
    ).run()
  File "/home/airflow/.local/lib/python3.10/site-packages/pymongo/synchronous/mongo_client.py", line 2709, in run
    return self._read() if self._is_read else self._write()
  File "/home/airflow/.local/lib/python3.10/site-packages/pymongo/synchronous/mongo_client.py", line 2819, in _write
    self._server = self._get_server()
  File "/home/airflow/.local/lib/python3.10/site-packages/pymongo/synchronous/mongo_client.py", line 2802, in _get_server
    return self._client._select_server(
  File "/home/airflow/.local/lib/python3.10/site-packages/pymongo/synchronous/mongo_client.py", line 1791, in _select_server
    server = topology.select_server(
  File "/home/airflow/.local/lib/python3.10/site-packages/pymongo/synchronous/topology.py", line 409, in select_server
    server = self._select_server(
  File "/home/airflow/.local/lib/python3.10/site-packages/pymongo/synchronous/topology.py", line 387, in _select_server
    servers = self.select_servers(
  File "/home/airflow/.local/lib/python3.10/site-packages/pymongo/synchronous/topology.py", line 294, in select_servers
    server_descriptions = self._select_servers_loop(
  File "/home/airflow/.local/lib/python3.10/site-packages/pymongo/synchronous/topology.py", line 344, in _select_servers_loop
    raise ServerSelectionTimeoutError(
pymongo.errors.ServerSelectionTimeoutError: localhost:27017: [Errno 111] Connection refused (configured timeouts: socketTimeoutMS: 20000.0ms, connectTimeoutMS: 20000.0ms), Timeout: 30s, Topology Description: <TopologyDescription id: 68065f276016a301faef871c, topology_type: Unknown, servers: [<ServerDescription ('localhost', 27017) server_type: Unknown, rtt: None, error=AutoReconnect('localhost:27017: [Errno 111] Connection refused (configured timeouts: socketTimeoutMS: 20000.0ms, connectTimeoutMS: 20000.0ms)')>]>
[2025-04-21T15:07:52.711+0000] {taskinstance.py:1138} INFO - Marking task as UP_FOR_RETRY. dag_id=prices_dag, task_id=save_to_excel, execution_date=20250421T150709, start_date=20250421T150719, end_date=20250421T150752
[2025-04-21T15:07:52.726+0000] {standard_task_runner.py:107} ERROR - Failed to execute job 32 for task save_to_excel (localhost:27017: [Errno 111] Connection refused (configured timeouts: socketTimeoutMS: 20000.0ms, connectTimeoutMS: 20000.0ms), Timeout: 30s, Topology Description: <TopologyDescription id: 68065f276016a301faef871c, topology_type: Unknown, servers: [<ServerDescription ('localhost', 27017) server_type: Unknown, rtt: None, error=AutoReconnect('localhost:27017: [Errno 111] Connection refused (configured timeouts: socketTimeoutMS: 20000.0ms, connectTimeoutMS: 20000.0ms)')>]>; 250)
[2025-04-21T15:07:52.767+0000] {local_task_job_runner.py:234} INFO - Task exited with return code 1
[2025-04-21T15:07:52.781+0000] {taskinstance.py:3280} INFO - 0 downstream tasks scheduled from follow-on schedule check
